Workbook

Sheet Snowflake YT Channel
A1: Scheduled / Published | B1: YouTube Publishing Date | D1: Time of Publishing (PST) | E1: Title / Wrike | F1: Social Request Submitted? | G1: Producer | H1: Playlist Designated? | I1: MP4 | J1: THUMB | K1: NOTES | L1: LENGTH OF VIDEO | N1: YT Link | O1: Thumbnail Title | P1: YouTube Title | Q1: YouTube Description | R1: Link to Thumbnail LINK TO THUMBNAIL FOLDER | S1: Link to Video Transcript | T1: Link to Social Cut | U1: Link to Social Cut on LI | V1: Link to Social Cut on X | X1: Tally - Summit (shorts are duplicated in Shorts column) | Y1: Tally - Customer | Z1: Short | AA1: Tally - Demos | AB1: Tally - Individual Videos | AC1: Snow Report | AD1: Tally - Podcast | AE1: Tally - promos | AF1: Tally - International Channel | AG1: Tally - BuiltBy | AH1: Tally-event workshops | AI1: Feature Friday | AJ1: Temp tally - PbS | AK1: BUILD | AL1: Tally - Horizon | AM1: Tally -Truck Talk
B2: Day | C2: Date | L2: Minutes | M2: Seconds
B3: NOTE: The YouTube tracking sheet for 2024 and 2023 can be found by clicking here.
B4: Wed | C4: 45693 | D4: 8 a.m. | E4: Accelerate 2025 Teaser | G4: x | H4: NA | K4: MP4; Wrike; done | L4: 1 | M4: 12 | O4: Accelerate 2025 | P4: Accelerate 2025 | Registration Is Now Open For This Virtual Event Series That Runs From March - April | Q4: Accelerate, Snowflake’s annual virtual event series, showcases how industry technology leaders are accelerating with data and AI strategies using The AI Data Cloud. Learn about the blueprints of an enterprise data architecture that puts secure self-service data consumption at its core. Hear about the latest AI / ML use cases driving efficiencies AND new data experiences. See customer proof points, demos, and real-world use cases that turn the art of the possible into real implementations. VIRTUAL EVENT DATES: Financial Services - March 6, 2025 Retail & Consumer Goods - March 20, 2025 Manufacturing - March 27, 2025 Advertising, Media & Entertainment - April 3, 2025 Public Sector - April 24, 2025 Healthcare & Life Sciences - April 30, 2025 Register now at https://www.snowflake.com/Accelerate | R4: Link | AE4: 1
A24: WEEK 6 | B24: 2/02 - 2/06
A25: TRUE | B25: Tues | C25: 46056 | E25: (Ice, Steel & Data) Frank Del Duca | G25: Jason | J25: https://files.wrike.com/1989536/669893874 | K25: See TRACKER for details | N25: https://youtu.be/d6IYxIq1OCo | R25: Approved thumbnail
A26: TRUE | B26: Thurs | C26: 46058 | E26: BUILD London 2026 Opening Keynote | G26: Bobby | J26: https://files.wrike.com/1989536/675862000 | N26: https://youtu.be/9LOP86qaw34 | O26: CORTEX CODE GA | P26: Snowflake Build London Keynote | Q26: Tune into the BUILD London Keynote. Hear what’s new from Snowflake - Shared Workspaces and the GA release of Cortex Code to Snowflake Postgres, semantic view autopilot, and interactive workloads for low-latency analytics. See demos across Snowflake ML, including notebooks in Workspaces, model registry, and online inference, plus how Cortex Agents API and Snowflake Intelligence help teams build trusted agent apps. The keynote also covers Snowflake’s partnership with OpenAI and why governance stays central as AI moves from answers to action.
A27: WEEK 7 | B27: 2/09 - 2/13 | W27: FALSE
A28: TRUE | B28: Mon | C28: 46062 | E28: Olympic commercial | G28: Jason | I28: SNOWFLAKE_Social.mp4 | J28: https://www.wrike.com/open.htm?id=4369560148 | N28: https://youtu.be/phT1wRZGUi8 | O28: Powering Team USA | P28: Snowflake Powers Team USA | Q28: Snowflake is proud to be the Official Data Collaboration Provider for Team USA. Team USA relies on Snowflake to unify their data and drive secure collaboration across the organization. It’s a partnership dedicated to innovation, ensuring that the team behind the Team has the insights they need to succeed. | W28: FALSE
A29: TRUE | B29: Mon | C29: 46062 | E29: SOCIAL: BUILD London Opening Keynote Sizzle | G29: Elani | J29: https://www.wrike.com/open.htm?id=4363419405 | N29: https://youtube.com/shorts/6kojZpCB93k
A30: TRUE | B30: Tues | C30: 46063 | E30: History of Skeleton | G30: Jason | I30: V16 History of Skeleton_Prt1_Cut01_020226.mp4 | J30: YouTube_Thumb-BSS_History_of_Skeleton-A3.jpg | K30: See TRACKER for details | N30: https://youtu.be/rqioJgLxhCo
A31: TRUE | B31: Tues | C31: 46063 | E31: SOCIAL: PS Kargo Video | G31: Elani | H31: x | I31: 26-PRG - SocialPSKargo_020626_AB_v2.mp4 | N31: https://youtube.com/shorts/sd5D2sO-3lM
A32: TRUE | B32: Wed | C32: 46064 | E32: Austin Florian | G32: Jason | I32: AustinFlorian_Athlete_EDIT_v12.mp4 | J32: YouTube_Thumb-BSS_History_of_Skeleton-A3.jpg | K32: See TRACKER for details | N32: https://youtu.be/piip_h8k3rg
A33: TRUE | B33: Wed | C33: 46064 | E33: BUILD London Vendor Cut | I33: https://next.frame.io/share/0e1f64ca-2222-4f2e-870d-ff8faa04e14b/view/1f28a5ab-84e6-4813-9143-22b38028113a | J33: https://www.wrike.com/open.htm?id=4372719906 | N33: https://youtu.be/qb2NuWOItQ4 | O33: BUILD LONDON 2026 | P33: Snowflake Build London Highlights | Q33: Recap the action from Snowflake Build London 2026. From the biggest moments to product announcements, to technical deep dives, and hands-on labs.
A34: TRUE | B34: Thurs | C34: 46065 | E34: History of Bobsled | G34: Jason | I34: Main Cut | J34: Thumbnail | K34: See TRACKER for details | N34: https://youtu.be/9uzcfLM5e5Q
A35: TRUE | B35: Fri | C35: 46066 | E35: February Snow Report | G35: Jason | I35: 26-PRG-SR February 2026_021026_MP_v4_1.mp4 | J35: https://files.wrike.com/1989536/677783296 | N35: https://youtu.be/K2DQKUGRe-A | O35: Snow Report February 2026 | P35: Snow Report: What's Happening At Snowflake In February | Q35: Get the latest Snowflake updates and announcements from February, including new innovations across the AI Data Cloud. This Snow Report covers the general availability of Cortex Code, Snowflake’s native AI coding agent, now available in Snowside and the command line to help teams move faster from question to action. You will also hear about upcoming and on-demand events, including webinars, hands-on virtual labs, and major community moments designed to help data and AI teams build production-ready agents, scale generative AI initiatives, and connect with the Snowflake community.
A36: TRUE | B36: Sat | C36: 46067 | E36: Kaysha Profile Part 2 | G36: Jason | I36: KayshaLove_Pt2_Cut10_021126_JF.mp4 | J36: BSS Kaysha Love Winter Games - A1.jpg | K36: See TRACKER for details | N36: https://youtu.be/2jCJZACeqLw | P36: Kaysha Love Finds A Winning Edge With Data | Q36: Team USA bobsled pilot Kaysha Love is gearing up for the Winter Olympics. Using Snowflake's Data Collaboration Platform, she turns raw track data and equipment choices into measurable performance gains. Hear what it really feels like to race at full speed, the gear she uses, and why confidence comes from mastering every detail and trusting the data.
A37: WEEK 8 | B37: 2/16 - 2/20 | W37: FALSE
A38: TRUE | B38: Tues | C38: 46070 | D38: x | E38: Jasmine Jones | G38: Jason | I38: JasmineJones__Prt1_Cut11_020526_WR.mp4 | J38: BSS Jasmine-Jones-Profile.jpg | K38: See TRACKER for details | L38: 1 | M38: 56 | N38: https://youtu.be/bjbqISUZDJg | O38: ATHLETE PROFILE: JASMINE JONES | P38: The Data Behind Jasmine Jones’ Fast Start | Q38: Jasmine Jones is a brakeman for USA Bobsled who knows the start can define the entire run. In this athlete profile, Jasmine breaks down her technique, body positioning, and split-second decisions that turn a push into podium speed. From step-in versus long-jump loading to reading velocity and start times against the field, she explains how trusting her training and the data helps her attack every run. With support from Snowflake’s Data Collaboration Platform, teams can align around what matters most as Jasmine embraces the challenge at Milano Cortina 2026.
A39: WEEK 9 | B39: 2/23 - 2/27 | W39: FALSE
A40: TRUE | B40: Mon | C40: 46076 | E40: Cortex Code "Announcement" motion graphics video | G40: Elani | N40: https://youtu.be/XV_Cs4DfZ4o
A41: TRUE | B41: Tues | C41: 46077 | E41: CS - NZHL x Deloitte Video | G41: Bobby | I41: NZHL Video (with subtitles).mp4 | J41: https://www.wrike.com/open.htm?id=4375017083 | N41: https://youtu.be/IlJcjgxx_yI | O41: AI-READY DATA FOUNDATION | P41: How NZHL Builds AI-Ready Data With Snowflake | Q41: Learn how New Zealand Home Loans replaces a fragmented, manual reporting environment with Snowflake to create a scalable, future-focused data foundation. By moving away from outdated tools and spreadsheets, NZHL establishes a trusted single source of truth that delivers faster insights and more consistent client experiences. With Snowflake, advisers prepare annual reviews at the push of a button using AI-powered insights, helping identify gaps and better support customers on their path to financial freedom. See how strong data foundations position NZHL to move quickly with AI and agentic AI, driving measurable business outcomes across people, process, data, and technology. | W41: FALSE
A42: TRUE | B42: Tues | C42: 46076 | D42: x | E42: Curt SI and Coaching with Data | G42: Jason | I42: CurtisTomasevicz_Coach_EDIT_v9.mp4 | J42: Curt SI and Coaching with Data - G-edit2.jpg | N42: https://youtu.be/JrQynsRTh6w
A43: TRUE | B43: Tues | C43: 46076 | D43: x | E43: CoCo - Customer Testimonial - WHOOP | G43: Elani | I43: 08-Released - WHOOP | J43: https://www.wrike.com/open.htm?id=4379695811 | W43: FALSE
A44: TRUE | B44: Wed | C44: 46078 | D44: x | E44: Curt's Path | G44: Jason | I44: CurtisTomasevicz_Coach_EDIT_2_v6.mp4 | J44: BSS Curts Path - A1 - Alt2.jpg | N44: https://youtu.be/b1XVYe0GFAM
A45: TRUE | B45: Wed | C45: 46078 | E45: CoCo - Customer Testimonial - Fanatics | G45: Elani | I45: 08-Released - Customer -Fanatics | J45: https://www.wrike.com/open.htm?id=4379694614 | W45: FALSE
A46: TRUE | B46: Thurs | C46: 46079 | E46: CoCo - Customer Testimonial - Shelter Insurance | G46: Elani | J46: https://www.wrike.com/open.htm?id=4379693904 | W46: FALSE
A47: TRUE | B47: Fri | C47: 46080 | D47: 0.33333333 | E47: Ordance Survey Customer Case Study Youtube Video | G47: Bobby | I47: 1169_-_sno_-_ordnance_survey_-_edit_v7_v1.mov | J47: https://www.wrike.com/open.htm?id=4384568207 | N47: https://youtu.be/mfBLAH-adTM | O47: Mapping Britain in Real-Time | P47: Ordnance Survey Transforms Geospatial Data Into Insight With Snowflake | Q47: Ash Wheeler, Chief Product Officer at Ordnance Survey, explains how they unlocked the power of geospatial data by migrating their National Geographic Database to the Snowflake AI Data Cloud. Learn how they’ve moved beyond traditional spreadsheets to offer instant, frictionless access to data for urban planning, emergency services, and environmental monitoring. | W47: FALSE
A48: WEEK 10 | B48: 3/02 - 3/06 | W48: FALSE
A49: TRUE | B49: Wed | C49: 46085 | E49: Tracksuit Video Case Study | G49: Bobby | I49: SWT_Tracksuit_CC_HD_FINAL.mp4 | J49: https://files.wrike.com/1989536/684673051 | N49: https://youtu.be/EAxOrdkEr8k | O49: BRAND INTELLIGENCE | P49: Tracksuit Delivers Always-On Brand Intelligence with Snowflake | Q49: With help from Snowflake, Tracksuit provides real-time, actionable performance insights to marketers, replacing static reports with a unified, AI-powered platform. | W49: FALSE
A50: TRUE | B50: Wed | C50: 46085 | E50: SOCIAL - Cortex Customer Testimonial - Lending Tree | G50: Elani | N50: https://youtube.com/shorts/Iz8MNf-h__M?si=rkCHqOEtUHhfzyYt | P50: LendingTree Scales Smarter Queries With Cortex Code | Q50: LendingTree uses Snowflake Cortex Code to speed up query development and deployment, eliminate context switching, and democratize data access across teams. | W50: FALSE
A51: TRUE | B51: Fri | C51: 46087 | E51: Bynder Case Study YouTube Video Request | G51: Bobby | I51: Bynder Customer Video.mov | J51: https://files.wrike.com/1989536/684687514 | K51: Pending Thumb | N51: https://youtu.be/EAxOrdkEr8k | O51: ENDING CONTENT CHAOS | P51: Bynder Eliminates Content Chaos With Snowflake | Q51: Learn how Bynder transforms digital asset management with Snowflake to eliminate data silos, improve performance, and scale with confidence. With more than 4,000 customers, 20 million assets uploaded quarterly, and 60 billion assets distributed each quarter, Bynder needs a data platform that keeps up. After moving to Snowflake, the team establishes a single source of truth across three data teams, processes massive CDN data sets, and scales without limits. The results: 60% cost reduction, 4x faster data ingestion, 2x faster data delivery, and nearly 50% productivity gains. See how Snowflake helps Bynder turn content chaos into actionable insight. | W51: FALSE
A52: WEEK 11 | B52: 3/09 - 3/13 | W52: FALSE
A53: TRUE | B53: Mon | C53: 46090 | E53: March Snow Report | F53: Sonia | I53: 26-PRG-SR - March 2026_030326_MP_FINAL.mp4 | J53: https://files.wrike.com/1989536/684501307 | K53: Pending Copy | N53: https://youtu.be/i6sVPVKPU30 | O53: MARCH SNOW REPORT | P53: Snow Report: What's Happening At Snowflake In March | Q53: Hear what’s new at Snowflake in March, from major product launches to upcoming community events, and more. Next generation Snowflake Notebooks are now generally available, delivering a familiar Jupyter-based experience directly in Snowflake workspaces. Online model inference in the online feature store is also generally available, enabling millisecond predictions for real-time use cases like fraud detection and personalized recommendations, with no extra infrastructure to manage. Plus, get the latest on Snowflake Summit 2026, Data for Breakfast, and March technical sessions covering AI pipelines, autonomous SQL, prompt-to-production workflows, and Apache Iceberg. | W53: FALSE
A54: TRUE | B54: Wed | C54: 46092 | E54: CoCo - Customer Testimonial - Dentisu | G54: Elani | H54: Cortex | I54: 08-Released - Braze | J54: https://www.wrike.com/open.htm?id=4379699048 | N54: https://youtube.com/shorts/ahiqBbxNq6A | O54: CORTEX CODE: RELIABILITY AT SCALE | P54: Dentisu Boosts AI Reliability With Snowflake Cortex Code | Q54: Dentisu shares how Snowflake Cortex Code improves reliability, streamlines AI workflows, and connects tools directly to the Snowflake AI Data Cloud. By using Cortex Code and the CLI as connective tissue between AI tools and Snowflake, Dentisu brings Snowflake context into the code generation layer. This closes the loop between development and production while supporting complex, market-specific variations at scale. Built-in code review capabilities catch broken syntax and risky patterns before they reach pipelines, reducing errors and strengthening performance. The result is faster iteration, greater reliability, and measurable return on investment powered by Snowflake. | W54: FALSE
A55: TRUE | B55: Fri | C55: 46094 | E55: Imperial College Healthcare NHS Trust YouTube Video | I55: Snowflake - NHS Imperial - Subtitled.mp4 | J55: https://files.wrike.com/1989536/684694184 | N55: https://youtu.be/CBaLM0qkIr0 | O55: SECURE DATA. BETTER CARE. | P55: Securely Transforming Healthcare Data In The AI Data Cloud | Q55: Learn how Imperial College Healthcare NHS Trust uses Snowflake to accelerate secure, data-driven healthcare across Northwest London. By implementing a Secure Data Environment, the Trust ingests and transforms data in days instead of weeks, enabling clinicians, data engineers, analysts, and researchers to collaborate in one unified platform. With access to Snowflake Marketplace data, including environmental data sets, teams can better predict demand, improve patient safety, and enhance care quality. See how Snowflake powers trusted, secure collaboration to support real-time insights, operational decision-making, and better patient outcomes across London. | W55: FALSE
A56: TRUE | B56: Fri | C56: 46094 | E56: CoCo - Customer Testimonial - Braze | G56: Elani | H56: Cortex | I56: 08-Released - Braze | J56: https://www.wrike.com/open.htm?id=4379695200 | N56: https://youtube.com/shorts/bOIWVovf0_o | O56: CORTEX CODE: FROM DATA TO ACTION | P56: Braze Goes Deeper Into Data With Cortex Code | Q56: Braze shares how Snowflake Cortex Code helps teams move faster and uncover deeper insights across structured and unstructured data. By simplifying complex analysis, Cortex Code reduces hours or days of effort into minutes. Braze uses it to explore customer engagement, from opens and clicks to downstream behaviors like purchases and subscriptions. The result is greater operational efficiency and the ability to pursue high-impact analyses that were previously too time intensive to justify. | W56: FALSE
A57: WEEK 12 | B57: 3/16 - 3/20 | W57: FALSE
A58: TRUE | B58: Mon | C58: 46097 | E58: SOCIAL - Cortex Code - Evolv Customer testimony | G58: Elani | H58: Cortex | I58: 3-RELEASED_Evolv | P58: Evolve Unlocks 500 Hours With Snowflake Cortex Code | Q58: Learn how Evolve uses Snowflake Cortex to accelerate development, eliminate backlogs, and deliver customer demos in hours instead of weeks. | W58: FALSE
A59: TRUE | B59: Wed | C59: 46099 | E59: SOCIAL - Anahita SnowWork Launch | G59: Elani | H59: Cortex | I59: 08-Released - Anahita SnowWork | P59: Introducing Project SnowWork | Q59: Introducing Project SnowWork. An autonomous AI platform that embeds intelligence directly into your business workflows and tools. | W59: FALSE
...

Sheet Dev YT Channel
A1: d | B1: YouTube Publishing Date | D1: Time of Publishing (PST) | E1: Wrike Request Name | F1: Social Request Submitted? | G1: Producer | H1: Playlist Designated? | I1: MP4 | J1: THUMB | K1: NOTES | L1: LENGTH OF VIDEO | N1: YT Link | O1: Thumbnail Title | P1: YouTube Title | Q1: YouTube Description | R1: Link to Thumbnail | S1: Link to Video Transcript | T1: Link to Social Cut MP4 | U1: Link to Social Cut on LI | V1: Link to Social Cut on X | X1: Summit (The shorts in this tally are duplicated in the Shorts column) | Y1: Demos | Z1: Shorts | AA1: Professional Services | AB1: Behind the Cape | AC1: Solutions Center (also marked as Demo) | AD1: User Groups | AE1: Individual Videos | AF1: Events | AG1: BUILD/Builder Bytes | AH1: Customer | AI1: AI Builders | AJ1: Podcast
A2: WEEK 6 | B2: 2/02 - 2/06
A3: TRUE | B3: Mon | C3: 46055 | E3: Behind The Cape - Snowflake Apache Iceberg and Polaris - Saurabh Kumar | G3: Bobby | I3: Behind the Cape - Apache Iceberg and Polaris Final.mp4 | J3: https://www.wrike.com/open.htm?id=4359850229 | L3: 30 | M3: 11 | N3: https://youtu.be/glDWNpHX8g4 | O3: OPEN CATALOG + ICEBERG | P3: Behind The Cape - Snowflake Apache Iceberg and Polaris | Q3: In this episode of Behind the Cape, Data Superhero Keith Belanger hosts fellow Data Superhero Saurabh Kumar as he breaks down how Snowflake, Apache Iceberg, and Apache Polaris are coming together to redefine what a modern, interoperable lakehouse really looks like. They chat through why open table formats and open catalogs matter more than ever, how Snowflake integrates with Iceberg and Polaris to support cross-cloud interoperability, and how teams can maintain vendor neutrality without sacrificing enterprise-grade performance, security, or governance.
A4: TRUE | B4: Mon | C4: 46055 | E4: Snowflake Postgres 2 minute demo | G4: Elani | I4: 26-PRG - Snowflake Postgres demo_020226_MP_v6.mp4 | J4: https://files.wrike.com/1989536/675754084 | L4: 2 | M4: 29 | N4: https://youtu.be/HhzpDM36Pzg | O4: POSTGRES ON SNOWFLAKE!? | P4: Snowflake Postgres In 2 Minutes: Fully Managed Postgres On Snowflake | Q4: Snowflake Postgres brings the world’s most popular open source database onto the Snowflake platform in a fully managed way. See how it unifies transactional and analytical workloads, and how developers can get started in minutes directly from Snowsight. The demo walks through provisioning an instance, connecting with standard Postgres tools, and using familiar features like extensions and permissions. You also learn how Snowflake Postgres simplifies operations with built in insights for performance, storage, and long running queries. Find out more: https://www.snowflake.com/postgres
A5: TRUE | B5: Tues | C5: 46056 | E5: DuckDB querying Snowflake-managed Apache Iceberg via Horizon (Iceberg REST) Catalog | G5: Elani | I5: 26-PRG - DuckDBQuerying_012125_AB_v2.mp4 | J5: https://files.wrike.com/1989536/674725516 | L5: 4 | M5: 51 | N5: https://youtu.be/vpbUbh4KRwo | O5: ICEBERG WITH DUCKDB | P5: Query Snowflake Managed Iceberg Tables With DuckDB | Q5: This demo shows how to query Snowflake managed Apache Iceberg tables using DuckDB through the Snowflake Horizon Iceberg REST Catalog. What you'll learn: • Set up Snowflake's Horizon Catalog for external engine access • Configure DuckDB with PAT (Programmatic Access Token) authentication • Query Iceberg tables from DuckDB with zero data movement • Handle RBAC and common troubleshooting scenarios Resources: https://github.com/kameshsampath/hirc-duckdb-demo
A6: TRUE | B6: Wed | C6: 46058 | E6: Online ML demo | G6: Sonia | I6: Online ML Demo_3.mp4 | J6: https://files.wrike.com/1989536/675871734 | L6: 11 | M6: 44 | N6: https://youtu.be/jnjQaYTNq6k | O6: REAL-TIME FRAUD ML | P6: Build and Serve Real-Time Fraud Detection Models in Snowflake ML | Q6: Moving ML from experimentation to production shouldn't require rebuilding from scratch or navigating lengthy development cycles. In this video, learn how to build, test, and deploy online ML models directly from Snowflake using an agentic approach to generate production-ready pipelines from simple natural language prompts.
A7: TRUE | B7: Wed | C7: 46057 | E7: SOCIAL: Anahita CoCo Social Video | G7: Elani | I7: 26-PRG - Anahita CoCo Social Video_012926_MP_v5.mp4 | J7: n/a | L7: 1 | M7: 13 | N7: https://youtube.com/shorts/XzPw-BfPkGw
A8: TRUE | B8: Thurs | C8: 46058 | E8: Snowflake Intelligence + Domo: Marketing Mix Modeling Integration | G8: Bobby | I8: 26-PRG - Snowflake Intelligence + Domo - Marketing Mix Modeling Integration_012726.mp4 | J8: https://files.wrike.com/1989536/675738167 | L8: 15 | M8: 28 | N8: https://youtu.be/9p2jYKR13QY | O8: CONVERSATIONAL MMM WITH AI | P8: Conversational Marketing Mix Modeling With Snowflake Intelligence | Q8: Andreina Toledo, Partner Solutions Consultant at Domo, demonstrates how to build conversational AI for Marketing Mix Modeling using Domo and Snowflake Intelligence. Marketing teams are constantly asked which channels truly drive results. Traditional platform metrics show clicks and conversions but cannot separate correlation from causation or measure true incremental impact. Domo MMM addresses this gap using Bayesian statistical modeling to analyze historical marketing spend alongside revenue, accounting for seasonality, carryover effects, and diminishing returns to deliver confidence-based ROI insights. What sets Domo MMM apart is how teams interact with these insights. By integrating with Snowflake Intelligence, Domo adds a conversational layer on top of MMM results. Marketers can ask natural language questions like which channels to prioritize or why spend should shift and receive clear, actionable answers grounded directly in the underlying analysis. Learn More: https://www.snowflake.com/en/developers/guides/domo-mmm-guide/
A9: TRUE | B9: Fri | C9: 46059 | E9: Keyless Data Engineering: AWS Lambda & Snowflake WIDF Explained | G9: Elani | I9: 26-PRG - Keyless Data Engineering: AWS Lambda | J9: https://files.wrike.com/1989536/675730159 | N9: https://youtu.be/gAVPzo0VJZ0 | O9: KEYLESS DATA WITH AWS LAMBDA | P9: Keyless Data Engineering With Snowflake And AWS Lambda | Q9: Learn how to build a secure, serverless data pipeline using Snowpark Python, AWS Lambda, and Snowflake Workload Identity Federation. You will see how an S3 event triggers Lambda, how temporary credentials are exchanged using identity federation, and how data is written securely into Snowflake. The walkthrough covers deployment, trust configuration, and validation, ending with Snowflake Dynamic Tables automatically refreshing as new data arrives. This pattern combines strong security with serverless speed for modern data engineering workflows. 👉 Get the demo code and documentation: https://github.com/kameshsampath/snowpark-widf-lambda-loader-demo
A10: WEEK 7 | B10: 2/09 - 2/13 | W10: FALSE
A11: TRUE | B11: Tues | C11: 46063 | E11: How to Integrate Akave Cloud with Snowflake | G11: Bobby | I11: 26 - PRG - How to Integrate Akave Cloud with Snowflake.mp4 | J11: https://files.wrike.com/1989536/675870896 | N11: https://youtu.be/OexaY_Qz5to | O11: AKAVE CLOUD INTEGRATION | P11: How to Integrate Akave Cloud with Snowflake | Q11: Bart Hofkin, Systems Architect at Akave, walks through how to integrate Akave Cloud with Snowflake. In this demo, you’ll see how to create an Akave bucket, configure it as an external stage in Snowflake, and read and write data between Snowflake and Akave using standard Snowflake workflows. This video is a step-by-step walkthrough focused on setup and usage, showing how S3-compatible object storage can be used directly within Snowflake. For more details and written instructions, refer to the Akave + Snowflake integration guide: https://akave.com/blog/akave-cloud-the-first-decentralized-object-storage-integrated-with-snowflake
A12: WEEK 8 | B12: 2/16 - 2/20 | W12: FALSE
A13: TRUE | B13: Fri | C13: 46073 | E13: BUILD London Cortex Code Breakout Session | G13: Bobby | H13: Coretex Code | I13: 08-Released - BUILD London CortexCode | J13: https://snowflake.enterprise.slack.com/files/U09J7RPTR7A/F0AGWTVBV4G/build25-dev_channel-center_title.png | N13: https://youtu.be/ZUJl6sUGnFk | O13: Cortex Code: Agents for Snowflake Development | P13: Cortex Code: The Purpose Built Agent for Snowflake Development | Q13: The process of building production-ready applications can have a lot of friction points - wrestling with connections, debugging permissions, and generating repetitive, complex configurations. If you spend more time managing the platform than writing business logic, your productivity is suffering. We believe your terminal should be a launchpad for innovation, not a place to solve administrative puzzles. This is the core mission of Cortex Code. This session introduces the new agentic CLI that puts the collective expertise of Snowflake directly into your command line. Through a rapid-fire live demonstration, we’ll show you how to use simple, natural language commands to instantly scaffold entire Snowpark projects, generate secure SQL, and orchestrate complex multi-step deployments. Discover how Cortex Code becomes your resident expert, allowing you to focus purely on value creation. | W13: FALSE
A14: TRUE | B14: Fri | C14: 46073 | E14: Cortex Code Overview | G14: Elani | H14: Cortex Code | I14: 26_PRG - CC_101__Overview_021626_AB_v5.mp4 | J14: https://www.wrike.com/open.htm?id=4379417935 | N14: https://youtu.be/lftWaAcG2nE | O14: All your data, one AI Coding agent | P14: Cortex Code CLI Expands to Support Any data, Anywhere | Q14: Learn what is new in Cortex Code CLI and how it accelerates your enterprise data lifecycle inside Snowflake. Introducing dbt and Apache Airflow support, expanded model choice across Claude Opus 4.6, Sonnet 4.6, and GPT 5.2, new enterprise-grade governance controls, and a self-serve subscription option. See how Cortex Code CLI helps you ship workflows faster, integrate data systems, and build with confidence using natural language. | W14: FALSE
A15: WEEK 9 | B15: 2/23 - 2/27 | W15: FALSE
A16: TRUE | B16: Mon | C16: 46076 | D16: 0.33333333 | E16: SOCIAL - Cortext Code Overview | G16: Elani | H16: Cortex Code | I16: 26_PRG - CC_Social_101_Overview_022026_AB_v6.mp4 | J16: https://www.wrike.com/open.htm?id=4379417935 | W16: FALSE
A17: TRUE | B17: Mon | C17: 46076 | E17: Cortex Code Overview (101) - Basics - Cortex Code | G17: Elani | H17: Cortex Code | W17: FALSE
A18: TRUE | B18: Tues | C18: 46077 | D18: 0.47916667 | E18: Accelerate FY27 | Teaser Trailer | F18: Elani | G18: Elani | I18: 08-Released - Accelerate26_Trailer | J18: https://www.wrike.com/open.htm?id=4367247238 | N18: https://youtu.be/04AkmzB0QP0 | O18: ACCELERATE 2026 | P18: Accelerate 2026: Industry AI Transformation With Snowflake | Q18: Learn how AI is transforming six major industries and how to build a practical, industry-ready AI strategy with Snowflake. Registration is now open. 👉 https://www.snowflake.com/accelerate Accelerate, Snowflake’s flagship virtual series, returns April 21 with two weeks of deep industry insight across advertising, media and entertainment, retail and consumer goods, public sector, financial services, manufacturing, and healthcare and life sciences. Hear from leaders across the AI and data ecosystem, including SAP and Accenture, and explore real-world use cases, Enterprise Super Intelligence architectures, semantic views, and connected data strategies in the AI Data Cloud. | W18: FALSE
A19: TRUE | B19: Tues | C19: 46077 | D19: 0.52083333 | E19: Openflow Oracle CDC | G19: Bobby | I19: 08-Released - Project Title | J19: https://www.wrike.com/open.htm?id=4382441783 | N19: https://youtu.be/nLGnb1VoJuc | O19: Near Real-Time Oracle CDC to Snowflake | P19: How-to Set Up Near Real-Time Oracle CDC to Snowflake using Openflow | Q19: Learn how to leverage Snowflake Openflow to establish near real-time Change Data Capture (CDC) replication from your Oracle database directly to Snowflake. This video showcases how Openflow ensures your critical transactional data from Oracle is unified and always up-to-date in Snowflake.
A20: TRUE | B20: Tues | C20: 46077 | E20: SOCIAL: DBT101 | G20: Elani | H20: Cortex Code | I20: 26-PRG - CC_Social_101_Dbt_022326_V4.mp4 | N20: https://youtube.com/shorts/SXKnsd9j6dY | W20: FALSE
A21: TRUE | B21: Wed | C21: 46077 | D21: 0.0625 | E21: Airflow - Debugging a failed DAG run | G21: Elani | H21: Cortex Code | I21: 4_Airflow_Released | J21: https://www.wrike.com/open.htm?id=4379708564 | W21: FALSE
A22: TRUE | B22: Thurs | C22: 46078 | E22: SOCIAL: Airflow | G22: Elani | H22: Cortex Code | I22: 26-PRG - CC_Social_Airflow_022626_AB_v3.mp4 | W22: FALSE
A23: TRUE | B23: Thurs | C23: 46078 | E23: Optimizing dbt for speed and cost (201) - Cortex Code | G23: Elani | H23: Cortex Code | I23: 08-Released - Coco_Customer_ShelterIns | J23: https://www.wrike.com/open.htm?id=4379690455 | O23: Optimize dbt Projects for Speed | P23: Optimize dbt Projects on Snowflake for Speed With Cortex Code | Q23: dbt projects on Snowflake are easy to build, but keeping them fast and cost-efficient is another challenge. As source tables grow and models become more complex, runtimes increase and performance issues get harder to pinpoint. In this demo, you'll see how to direct Cortex Code CLI to analyze your project’s run_results.json, identify the slowest models, flag unused ones, and find suggestions for specific optimizations you can apply immediately, all from a single prompt in your terminal. | W23: FALSE
A24: WEEK 10 | B24: 3/02 - 3/06 | W24: FALSE
A25: TRUE | B25: Tues | C25: 46083 | E25: Demo videos for newly launched enterprise-grade sharing | G25: Bobby | I25: 26-PRG - Enterprise-grade sharing_030326_MP_v1.mp4 | J25: https://files.wrike.com/1989536/683191137 | N25: https://youtu.be/H-l8IgbIlqE | O25: Data Product Resiliency | P25: Enterprise-grade Sharing Demo Videos - Part 1: Listing BCDR | Q25: Explore how Snowflake Listing BCDR, helps customer's to streamlines data product protection with automated failover and seamless recovery workflows. See firsthand how this enterprise-grade sharing capability minimize downtime and keep your critical data product resilient against any disruption. | W25: FALSE
A26: TRUE | B26: Tues | C26: 46083 | E26: Demo video for Resharing GA | G26: Bobby | I26: 26-PRG -Resharing GA_030326_MP_v1.mp4 | J26: https://www.wrike.com/open.htm?id=4384622738 | N26: https://youtu.be/EJsJ2qNK41s | O26: Zero-ETL Data Enrichment | P26: Data Product Enrichment With Zero-ETL Transformations: Resharing GA | Q26: Resharing, a new Snowflake AI & Data sharing feature that builds on our Zero-ETL, cross-cloud and cross-region capabilities, allows customers to reuse shared data products without having to manage local copies (materialize) and apply light-weight transformations on the fly. Resharing can help customers simplify their sharing architecture by providing simple, light-weight transformation for shared data product enrichment, without having to move, extract or load the data. | W26: FALSE
A27: TRUE | B27: Tues | C27: 46084 | E27: Cortex Code - dbt core | G27: Elani | H27: Cortex Code | N27: https://youtu.be/airYxlLRTBE | O27: FASTER dbt CORE BUILDS | P27: Make Your dbt Core Builds Faster with Cortex Code | Q27: When dbt builds fail or pipelines slow down, Cortex Code CLI accelerates troubleshooting by bringing Snowflake expertise directly to your terminal. By reading your project files—including models, tests, and lineage—without requiring a manual compile, it can instantly identify bottlenecks, perform blast radius analysis, and audit test coverage. This data-native AI agent combines dbt project structure with Snowflake query history to provide a prioritized improvement plan, allowing you to trace dependencies and refactor code from a single prompt with total confidence.
A28: TRUE | B28: Thurs | E28: SOCIAL: Ddbt 201 | G28: Elani
A29: TRUE | B29: Fri | C29: 46085 | D29: x | E29: Cortex Code - Building Agents Demo | G29: Elani | H29: Cortex Code | I29: 26_PRG - CC_201_BuildingDataAgents_030426_AB_v5.mp4 | N29: https://youtu.be/wKvVkHO0fOw | O29: AI Agents That Scale | P29: Ship AI Agents Fast with Cortex Code CLI | Q29: Vibe-coded agents can look impressive, but they often become brittle when exposed to real enterprise data. In this walkthrough, we use Cortex Code CLI to build a Cortex Agent powered directly by governed Snowflake data. We combine structured metrics, unstructured search, routing logic, and guardrails, then deploy to Snowflake Intelligence. | W29: FALSE
A30: WEEK 11 | B30: 3/09 - 3/13 | W30: FALSE
A31: TRUE | B31: Tues | C31: 46091 | E31: SOCIAL: Cortex Code - Building Agents Demo | G31: Elani | H31: Cortex Code | I31: 26_PRG - CC_Social_201_BuildingDataAgents_030426_AB_v2.mp4 | W31: FALSE
A32: TRUE | B32: Wed | C32: 46092 | E32: SOCIAL: Cortex Code - dbt core | G32: Elani | H32: Cortex Code
A33: TRUE | B33: Wed | C33: 46092 | E33: Cortex Code - Data Exploration Demo | G33: Elani | H33: Cortex Code | O33: From Data Chaos to Clarity | P33: Rapid Data Exploration with Cortex Code CLI | Q33: Data exploration usually means inspecting schemas, profiling columns, and writing exploratory code just to understand what’s there. In this demo, we use Cortex Code CLI to handle that work directly from the terminal on real Snowflake data. Anything you want to understand in your data, just ask Cortex Code. | W33: FALSE
A34: TRUE | B34: Thurs | C34: 46093 | E34: How To Build A Churn Insights Agent Using Snowflake Intelligence | G34: Sonia | H34: professional svcs | I34: 26-PRG - How To Build A Churn Insights Agent Using Snowflake Intelligence_WR_03092026.mp4 | J34: https://www.wrike.com/open.htm?id=4364867447 | N34: https://youtu.be/ELf1LpzgxTc | O34: REDUCE CUSTOMER CHURN | P34: Build A Churn Insights Agent With Snowflake Intelligence | Q34: In this video, we'll show you how to transform raw machine learning models into actionable AI insights. Using Snowflake Intelligence, you'll learn to build an AI Agent that: Leverages the Snowflake Model Registry to provide clear, transparent model explainability. Constructs a semantic layer of intelligence directly over your ML models. Bridges the gap for non-technical stakeholders to interact with complex data. Link to code: https://github.com/sfc-gh-sujoshi/sf-samples/tree/main/samples/churn_intelligence_agent Links to relevant documentation: https://www.snowflake.com/en/developers/guides/getting-started-with-snowflake-intelligence/ https://docs.snowflake.com/en/developer-guide/snowflake-ml/model-registry/overview Link to background music used throughout this video: https://www.fesliyanstudios.com/royalty-free-music/download/smooth-presentation/382 | W34: FALSE
A35: TRUE | B35: Thurs | C35: 46093 | E35: Horizon Catalog overview | G35: Bobby | I35: 26-PRG - SCQ4_HorizonCatalogOverview_031026_AB.mp4 | J35: https://www.wrike.com/open.htm?id=4402902969 | N35: https://youtu.be/S66kaS5uoVc | O35: HORIZON CATALOG POWERS AI | P35: Snowflake Horizon Catalog: Powering Trusted AI And Open Data | Q35: Learn how Snowflake Horizon Catalog helps you build a data strategy that makes AI safe, trusted, and scalable. Get an overview of interoperability with Apache Iceberg and open standards, discovery with hybrid search, lineage and observability, and semantic enrichment that improves agent accuracy. | W35: FALSE
A36: TRUE | B36: Fri | C36: 46094 | E36: Bi-directional Interoperability with Horizon Catalog demo | G36: Bobby | I36: 26-PRG - SCQ4_Bi-directionalInteroperability_031026_AB.mp4 | J36: https://www.wrike.com/open.htm?id=4402897474 | N36: https://youtu.be/4ld80bFUBq8 | O36: BI-DIRECTIONAL INTEROP DEMO | P36: Bi-Directional Interoperability With Snowflake Horizon Catalog | Q36: Learn how Snowflake Horizon Catalog enables bi-directional interoperability across your open lakehouse architecture. In this demo, Riccardo Muti shows how to create and manage Apache Iceberg tables in Snowflake, access them from external engines like Spark, and securely read and write data using the Iceberg REST Catalog API. You also see the reverse scenario: federating external catalogs such as AWS Glue into Snowflake for seamless query and write access. | W36: FALSE
A37: TRUE | B37: Fri | C37: 46094 | E37: Accelerate FY27 | Teaser Trailer | G37: Jason | I37: 26-PRG - Accelerate FY27 Teaser_031226_MP_v4.mp4 | N37: https://youtu.be/dm5SsNCmu68 | W37: FALSE
A38: WEEK 12 | B38: 3/16 - 3/20 | W38: FALSE
A39: TRUE | B39: Mon | C39: 46097 | E39: Data and AI Governance with Horizon Catalog | G39: Bobby | I39: 26-PRG - SCQ4_DataAndAIGovernance_031026_AB.mp4 | J39: https://www.wrike.com/open.htm?id=4402906865 | N39: https://youtu.be/42GWL5x3Xpg | O39: HORIZON CATALOG GOVERNANCE | P39: Horizon Catalog: Governing Data For Trusted AI | Q39: Learn how Horizon Catalog detects and protects sensitive data, enforces tag-based masking and automatic tag propagation, and delivers observability for lineage and data quality so AI can run safely on trusted data. This demo shows practical governance workflows in Snowflake. Creating classification profiles, applying tag-based masking policies, tracing column-level lineage, and using universal search and conversational discovery to find and understand data. | W39: FALSE
A40: TRUE | B40: Tues | C40: 46098 | E40: Semantic Views with Horizon Catalog | G40: Bobby | I40: 26-PRG - SCQ4_SemanticViews _031026_AB.mp4 | J40: https://www.wrike.com/open.htm?id=4402909705 | N40: https://youtu.be/6TUckfUdweE | O40: HORIZON CATALOG SEMANTIC VIEWS | P40: Semantic Views In Horizon Catalog | Q40: Learn how to create and use semantic views in Snowflake Horizon Catalog to make data understandable and actionable for both humans and AI. This video demonstrates how Cortex Analyst turns business prompts into correct SQL using semantic views, how to enrich metadata with descriptions, relationships, verified queries, and custom metrics, and how to expose agents via MCP so external AI tools can query your semantic models securely. | W40: FALSE
...

Sheet DCN YT Channel
A1: "Scheduled / Published" | B1: YouTube Publishing Date | D1: Time of Publishing (PST) | E1: Video Request [CONTENT MASTER] | F1: Producer | G1: Social Request Submitted? | H1: Playlist Designated? | I1: MP4 | J1: THUMB | K1: NOTES | L1: LENGTH OF VIDEO | N1: YT Link | O1: Thumbnail Title | P1: YouTube Title | Q1: YouTube Description | S1: Tally - Summt (shorts are dupulicated in Shorts column) | T1: Interviews | U1: Shorts | V1: Promos | W1: Special Reports
B2: Day | C2: Date | K2: Ryan's DCN Source of Truth can be found here | L2: Minutes | M2: Seconds | S2: 1
A3: WEEK 6 | B3: 2/02 - 2/06
A4: TRUE | B4: Mon | C4: 46055 | D4: 0.99305556 | E4: Product Exec Video - Snowflake & Microsoft | F4: Sonia | I4: 25-PRG - Product Exec Video - Snowflake Microsoft_v06_Deliverable.mp4 | J4: https://www.wrike.com/open.htm?id=4361272385 | N4: https://youtu.be/SNgPjz6pA1s | O4: ENTERPRISE ANALYTICS TOGETHER | P4: The Future Of Open Data Architectures With Snowflake And Microsoft | Q4: Arun Ulag, President of Azure Data at Microsoft, and Christian Kleinerman, Executive Vice President of Product at Snowflake discuss the major milestone of the bidirectional integration between Microsoft OneLake and Snowflake through Apache IcebergTM becoming generally available. Hear how Snowflake and Microsoft are partnering to help customers build a unified data foundation with interoperability at its core– empowering data teams to adapt as quickly as their businesses evolve without data movement. Interested to learn more? Read more about Microsoft OneLake and Snowflake interoperability on the Microsoft Fabric Blog. Visit this Snowflake developers page to get started and watch this step-by-step guided demo. Join the Data Cloud Now Community: https://bit.ly/3GdXtgD Learn more about Data Cloud Now: Website: https://www.TheDataCloudNow.com Podcast: https://bit.ly/3sFXst6 #MicrosoftFabric #Snowflake #ApacheIceberg #DataEngineering #Interoperability
A5: TRUE | B5: Wed | C5: 46057 | E5: SOCIAL: Data Cloud Now Energy Solutions Announcement Interview | F5: Sonia | I5: 26-PRG-DCN - SOCIAL_Energy Solutions_PG_v06.mp4 | N5: https://youtube.com/shorts/tHRCVXuDVCE
A6: TRUE | B6: Thurs | C6: 46058 | E6: SAP and Sridhar at Davos 2026 | F6: Sonia | I6: 26-PRG-SAP_SRIDHAR_020226_PG_v08.mp4 | J6: https://files.wrike.com/1989536/674713185 | N6: https://youtu.be/Pcr6oqqbxAA | O6: DAVOS 2026 [SAP LOGO] | [Snowflake Logo] | P6: SAP And Snowflake On Delivering Real ROI With Agentic AI | Q6: In this episode of Data Cloud Now, learn how the SAP and Snowflake partnership helps customers move from AI experimentation to measurable business value. Leaders from both companies share what they are hearing directly from customers, why large-scale AI deployments still struggle to show ROI, and how harmonized data and shared semantics unlock more impactful AI use cases. The conversation explores how combining operational SAP data with Snowflake analytics gives enterprises tangible proof of value, from sales and HR to finance and supply chain. You will also hear why agentic AI is becoming critical to the future of work, how it removes technical and organizational blockers, and what it takes to drive real adoption across the enterprise.
A7: TRUE | B7: Fri | C7: 46059 | E7: SOCIAL: Money 20/20 DCN PayPal | F7: Sonia | I7: 25-PRG-DCN - PayPal at Money2020_SOCIAL_PG_v03.mp4 | N7: https://youtube.com/shorts/tKUkJREDXlc
A8: WEEK 7 | B8: 2/09 - 2/13
A9: TRUE | B9: Mon | C9: 46062 | E9: SOCIAL: Product Exec Video - Snowflake & Microsoft | F9: Sonia | I9: 25-PRG - Product Exec Video - SOCIAL - Snowflake Microsoft_v02_Deliverable.mp4 | N9: https://youtube.com/shorts/WShWLDxNIX4
A10: TRUE | B10: Tues | C10: 46063 | E10: DCN Money2020 #3 (Fiserv) | F10: Sonia | I10: 25_DCN_Fiserv_Money2020_120525_PG_v01_Deliverables.mp4 | J10: https://www.wrike.com/open.htm?id=4328723900 | N10: https://youtu.be/wk9yV3xq0V0 | O10: DATA-DRIVEN PAYMENTS | P10: How Fiserv Use Data And AI To Personalize Payments | Q10: Learn how financial institutions and merchants use data and AI to deliver real-time, personalized payment experiences. Recorded at Money20/20, this episode of Data Cloud Now features Brandy Wood, Head of Client Experience Product at Fiserv, sharing how converged payments and loyalty data help drive hyper-personalization, customer retention, and revenue growth. Brandy explains how expectations for instant gratification are reshaping the payments ecosystem, why data must move beyond reconciliation to actionable insight, and how zero-copy data sharing on Snowflake reduces cost and complexity while enabling real-time collaboration with partners like PayPal. The conversation also explores how upstarts and established institutions work together on the AI Data Cloud to innovate securely and at scale.
A11: TRUE | B11: Wed | C11: 46064 | E11: DCN Predictions - Anahita + Vivek + Dwarak - Agents | F11: Sonia | I11: 25-PRG-DCN - Predictions_AnahitaVivekDwarak_020226_AB_v2.mp4 | J11: https://www.wrike.com/open.htm?id=4369503284 | N11: https://youtu.be/qPDT2XgbFb0 | O11: THE YEAR OF AI AGENTS | P11: AI + Data Predictions 2026 | Q11: Listen into AI + Data Prediction for 2026. They year enterprise leaders move beyond AI hype to put agents into production and drive measurable business outcomes. In this Data Cloud Now discussion, Snowflake leaders and experts share why 2026 is shaping up to be the year of AI agents, and what it takes to make them work at scale. The conversation explores why solving real business problems matters more than experimenting with AI for its own sake, how unified data platforms enable trustworthy agents, and why governance, semantics, and change management are critical. You will hear practical guidance on moving from prototypes to production, embedding agents into daily workflows, and using the AI Data Cloud to deliver reliable, high-impact results across the enterprise.
A12: TRUE | B12: Thurs | C12: 46065 | E12: Sridhar at Davos 2026 | F12: Sonia | J12: https://www.wrike.com/open.htm?id=4369508101 | N12: https://youtu.be/VVQ_WhhWsNA | O12: ROI ON AGENTIC AI | P12: Snowflake CEO On Agentic AI And ROI At Davos 2026 | Q12: Snowflake CEO Sridhar Ramaswamy talks with Ryan Green about key takeaways from Davos 2026. Hear how agent AI is reshaping enterprise strategy and business outcomes, and why clarity around what drives top line and bottom line growth is essential as AI capabilities accelerate. Sridhar outlines how agentic AI moves beyond chatbots to deliver real ROI, from replacing traditional dashboards to transforming customer support, life sciences, and analytics. He also explains why governed data platforms, model choice, and AI sovereignty matter for global enterprises, and what Snowflake is doing next to help customers deploy AI and agents faster at scale.
A13: TRUE | B13: Fri | C13: 46066 | E13: SOCIAL: SAP and Sridhar at Davos 2026 | F13: Sonia | I13: 26-PRG-SAP_SOCIAL_SRIDHAR_020226_PG_v06_CC.mp4 | N13: https://youtube.com/shorts/8u0ptDr4CFI
A14: WEEK 8 | B14: 2/16 - 2/20
A15: CONTENT FREEZE (OLYMPICS) | BI15: FALSE | BJ15: FALSE | BK15: FALSE | BL15: FALSE | BM15: FALSE | BN15: FALSE | BO15: FALSE
A16: WEEK 9 | B16: 2/23 - 2/27
A17: TRUE | B17: Tues | C17: 46077 | E17: SOCIAL: DCN Money2020 #3 (Fiserv) | F17: Sonia | I17: 25_DCN_Fiserv_Money2020_SOCIAL_120925_PG_v03_Deliverable.mp4 | J17: https://files.wrike.com/1989536/677629493 | N17: https://youtube.com/shorts/z1i2YZ18NJc
A18: TRUE | B18: Tues | C18: 46077 | E18: DCN Starburst | F18: Sonia | H18: https://f.io/Jt0gLhkH | J18: https://www.wrike.com/open.htm?id=4380385931 | N18: https://youtu.be/VsKtmVA6slM | O18: INTEROPERABLE DATA | P18: Snowflake And Starburst Power Interoperable AI Data | Q18: Learn how Snowflake and Starburst help organizations unify distributed data to power enterprise AI. In this episode of Data Cloud Now, Starburst Founder & CEO Justin Borgman explains why AI is fundamentally a data story and how interoperability, open standards like Apache Iceberg, and the Open Semantic Interchange enable governed, scalable access across platforms.
A19: TRUE | B19: Thurs | C19: 46079 | E19: SOCIAL: Sridhar at Davos 2026 | F19: Sonia | I19: 26-PRG-DCN - DavosSridhar_SOCIAL_021126_PG_v04_Deliverable.mp4 | N19: https://youtube.com/shorts/X7Z9tJc9OJ8
A20: TRUE | B20: Fri | C20: 46080 | E20: Christian Kleinerman at Davos 2026 | F20: Sonia | J20: https://www.wrike.com/open.htm?id=4382299202 | N20: https://youtu.be/HCQp4mDve_g | O20: AI Innovation At Davos | P20: Christian Kleinerman At Davos 2026 On AI Innovation | Q20: In this Davos 2026 interview, Christian Kleinerman, SVP of Product at Snowflake, shares how AI is reshaping data strategy and why 2026 is a defining year for enterprise innovation. From Snowflake Intelligence to Cortex Code, Christian explains how Snowflake helps organizations unlock insights from structured and unstructured data, simplify data operations, and accelerate decision-making. He also discusses interoperability, Iceberg tables, sovereign clouds, governance with Horizon Catalog, and how leaders can build teams ready to adapt in a fast-moving AI landscape.
A21: WEEK 10 | B21: 3/02 - 3/06 | W21: FALSE
A22: TRUE | B22: Mon | C22: 46083 | E22: SOCIAL: DCN Predictions - Anahita + Vivek + Dwarak - Agents | F22: Sonia | I22: 25-PRG-DCN - Predictions_AnahitaVivekDwarak_Social_022426_AB_v7.mp4 | N22: https://youtube.com/shorts/8OwLKa8YzME
A23: TRUE | B23: Tues | C23: 46084 | E23: Samsung Ads at AdWeek 2025 | F23: Sonia | I23: https://f.io/bcvzLz1N | J23: https://www.wrike.com/open.htm?id=4386330526 | N23: https://youtu.be/-W90t2VEjUM | O23: PRIVACY-FIRST ADS | P23: Samsung Ads Powers Privacy First CTV With Snowflake | Q23: Learn how Samsung Ads uses the Snowflake AI Data Cloud to power privacy first, full funnel advertising across streaming and linear TV. At Advertising Week in New York City, Samsung shares how advertisers shift from fragmented campaigns to unified planning across CTV, OTT, and linear. With more than 60 million households, Samsung Ads delivers actionable insights that reduce wasted impressions and duplicated reach. | W23: FALSE
A24: TRUE | B24: Wed | C24: 46085 | E24: SOCIAL: DCN Starburst | F24: Sonia | I24: 25_DCN_Starburst_SOCIAL_022526_v03_Deliverable.mp4 | N24: https://youtube.com/shorts/7srlli-yX88 | P24: Snowflake And Starburst Power Interoperable AI Data | W24: FALSE
A25: TRUE | B25: Wed | C25: 46085 | E25: Mike + Anahita + Chris - The Agent-Enabled Workforce | F25: Sonia | I25: https://f.io/KJcJbjXr | J25: https://www.wrike.com/open.htm?id=4386300829 | N25: https://youtu.be/027aEI-i3ro | O25: AI CO-WORKERS | P25: The Agent Enabled Workforce | Q25: Learn how AI agents are reshaping the enterprise and what it takes to build an agent enabled workforce in 2026. Snowflake leaders explore how agents evolve from assistants to virtual coworkers, transforming data engineering, analytics, and go to market teams. As AI adoption accelerates, success depends on strong data foundations, clear business context, and the ability to think like an agent. | W25: FALSE
A26: TRUE | B26: Thurs | C26: 46086 | E26: Mike Gannon at Davos 2026 | F26: Sonia | I26: 26-DCN-MikeGannon_Davos_030426_PG_v05_Deliverable.mp4 | J26: https://www.wrike.com/open.htm?id=4386331975 | N26: https://youtu.be/YbMMyhQgKMg | O26: AI AT DAVOS 2026 | P26: Snowflake At Davos: AI As A Competitive Advantage | Q26: Learn how Snowflake is turning AI into measurable business outcomes and competitive advantage in 2026. At Davos, Mike Gannon shares how leaders are moving from AI experimentation to enterprise wide prioritization. From case deflection that saves hundreds of hours to internal AI agents like Raven that deliver real time customer insights, Snowflake embeds AI across sales, support, and professional services. Discover how data sovereignty, governance, and observability are shaping global AI strategy, and why top down alignment is critical to scaling agent AI responsibly on the Snowflake AI Data Cloud. | W26: FALSE
A27: TRUE | B27: Fri | C27: 46087 | E27: SOCIAL: Christian Kleinerman at Davos 2026 | F27: Sonia | I27: 26-PRG-DCN-SOCIAL_ChristianKleinerman_DAVOS_021026_v04.mp4 | N27: https://youtube.com/shorts/Hw7NVXk9an4 | P27: Christian Kleinerman At Davos 2026 On AI Innovation | W27: FALSE
A28: WEEK 11 | B28: 3/09 - 3/13 | W28: FALSE
A29: TRUE | B29: Mon | C29: 46090 | E29: SOCIAL: Samsung Ads at AdWeek 2025 | F29: Sonia | I29: 25-PRG-DCN-Samsung_SOCIAL_PG_022526_v02.mp4 | N29: https://youtube.com/shorts/cYsXF5hc1yM | W29: FALSE
A30: TRUE | B30: Wed | C30: 46092 | E30: Brad Jones, CISO, Snowflake | F30: Sonia | I30: 25-PRG-DCN - Predictions_Brad_031026_AB_v3.mp4 | J30: https://www.wrike.com/open.htm?id=4390211799 | N30: https://youtu.be/FG4-dCQtgYE | O30: AI SECURITY | P30: Agentic AI And Cybersecurity In 2026 | Q30: In this predictions conversation Snowflake CISO Brad Jones shares how security teams are using AI for log analysis, case summarization, and workflow automation, and why governance, identity, and data protection must come first. He explains how attackers are leveraging generative AI across the full attack lifecycle, what consolidation in the AI security market could look like, and why building a controlled AI playground helps reduce sprawl. Discover how to apply the fundamentals while preparing your data and AI strategy for a fast-moving threat landscape. | W30: FALSE
A31: TRUE | B31: Wed | C31: 46092 | E31: SOCIAL: Mike + Anahita + Chris - The Agent-Enabled Workforce | F31: Sonia | I31: 25-PRG-DCN - Predictions_MikeAnahitaChris_SociaL_030326_AB_v6.mp4 | N31: https://youtube.com/shorts/IjXlabooA3M | W31: FALSE
A32: TRUE | B32: Thurs | C32: 46093 | E32: Accenture London | F32: Sonia | I32: 25-PRG-DCN - Accenture_PG_0030626_v03_Deliverable.mp4 | J32: https://www.wrike.com/open.htm?id=1759271086 | N32: https://youtu.be/8qiZ4claTaM | O32: SCALE AI WITH CONFIDENCE | P32: Scaling AI With Snowflake And Accenture | Q32: Learn how Snowflake and Accenture help enterprises scale AI with a strong data foundation and a people-first strategy. In this conversation from London, leaders share how organizations move from AI experimentation to enterprise-wide impact, and why every AI strategy requires a data strategy. Snowflake and Accenture combine platform and practice, with thousands of certified professionals and hundreds of enterprise engagements, to help customers accelerate innovation, reinvent operations, and keep a human in the loop. | W32: FALSE
A33: TRUE | B33: Fri | C33: 46094 | E33: SOCIAL: Mike Gannon at Davos 2026 | F33: Sonia | I33: 26-DCN-MikeGannon_Davos_SOCIAL_030426_PG_v08_Deliverable.mp4 | N33: https://youtube.com/shorts/mPomwB4-Hz4 | W33: FALSE
A34: WEEK 12 | B34: 3/16 - 3/20 | W34: FALSE
A35: TRUE | B35: Mon | C35: 46097 | E35: SOCIAL: Brad Jones, CISO, Snowflake | F35: Sonia | I35: 25-PRG-DCN - Predictions_Brad_Social_031025_AB_v4.mp4 | N35: https://youtube.com/shorts/xeYkFmzdESI | W35: FALSE
A36: TRUE | B36: Tues | C36: 46098 | E36: Snowflake @ NRF | F36: Sonia | I36: 26-DCN_Snowflake_NRF_031626_PG_v01_Deliverable.mp4 | J36: https://www.wrike.com/open.htm?id=4402884245 | N36: https://youtu.be/z3EII8B5NE0 | O36: AGENTS FOR RETAIL | P36: How AI Agents Transform Retail With Snowflake | Q36: AI agents are reshaping retail. From product discovery to supply chain automation, meaning data quality is now mission critical. Recorded live at NRF in New York City, Snowflake’s Rosemary DeAragon shares how retailers use AI from LLMs to agents to drive personalization, forecasting, and real-time decision-making. | W36: FALSE
A37: TRUE | B37: Thurs | C37: 46100 | E37: Microsoft London | F37: Sonia | I37: 25-PGM-DCN - Microsoft at SWT London_121025_RL_v1 (1).mp4 | J37: https://www.wrike.com/open.htm?id=4390212320 | N37: https://youtu.be/Irlai6ZCcLk | O37: AI Without Data Silos | P37: Snowflake And Microsoft Accelerate Enterprise AI In Europe | Q37: Learn how Snowflake and Microsoft are expanding interoperability across Fabric and the AI Data Cloud to accelerate enterprise AI adoption in Europe. In this conversation from London, leaders from Snowflake and Microsoft share how bidirectional data access and Iceberg table support help customers break down data silos and speed time to value. Hear how integrations across Teams, Power BI, Dynamics 365, and Microsoft Fabric enable natural language access to governed data. | W37: FALSE
A38: TRUE | B38: Fri | C38: 46101 | E38: SOCIAL: Accenture London | F38: Sonia | I38: 25-PRG-DCN - Accenture_SOCIAL_PG_031026_v05_Deliverable.mp4 | N38: https://youtube.com/shorts/XZNw3OmLd5Q | W38: FALSE
A39: WEEK 13 | B39: 3/23 - 3/27 | W39: FALSE
A40: TRUE | B40: Tues | C40: 46105 | E40: SOCIAL: Snowflake @ NRF | F40: Sonia | I40: 26-DCN_Snowflake_NRF_SOCIAL_031626_PG_v02_Deliverable.mp4 | N40: https://youtube.com/shorts/Cdf3hKbmcvg | W40: FALSE
...

Sheet International Channel
A1: Scheduled / Published | B1: YouTube Publishing Date | D1: Time of Publishing (PST) | E1: Title / Wrike | F1: Social Request Submitted? | G1: Producer | H1: Playlist Designated? | I1: MP4 | J1: THUMB | K1: NOTES | L1: LENGTH OF VIDEO | N1: YT Link | O1: Thumbnail Title | P1: YouTube Title | Q1: YouTube Description | R1: Link to Thumbnail LINK TO THUMBNAIL FOLDER | S1: Link to Video Transcript | T1: Link to Social Cut | U1: Link to Social Cut on LI | V1: Link to Social Cut on X | X1: Tally - Summit (shorts are duplicated in Shorts column) | Y1: Tally - Customer | Z1: Short | AA1: Tally - Demos | AB1: Tally - Individual Videos | AC1: Snow Report | AD1: Tally - Podcast | AE1: Tally - promos | AF1: Tally - International Channel | AG1: Tally - BuiltBy | AH1: Tally-event workshops | AI1: Feature Friday | AJ1: Temp tally - PbS | AK1: BUILD | AL1: Tally - Horizon | AM1: Tally -Truck Talk
B2: Day | C2: Date | L2: Minutes | M2: Seconds
B3: NOTE: The YouTube tracking sheet for 2024 and 2023 can be found by clicking here.
B4: Wed | C4: 45693 | D4: 8 a.m. | E4: Accelerate 2025 Teaser | G4: x | H4: NA | K4: MP4; Wrike; done | L4: 1 | M4: 12 | O4: Accelerate 2025 | P4: Accelerate 2025 | Registration Is Now Open For This Virtual Event Series That Runs From March - April | Q4: Accelerate, Snowflake’s annual virtual event series, showcases how industry technology leaders are accelerating with data and AI strategies using The AI Data Cloud. Learn about the blueprints of an enterprise data architecture that puts secure self-service data consumption at its core. Hear about the latest AI / ML use cases driving efficiencies AND new data experiences. See customer proof points, demos, and real-world use cases that turn the art of the possible into real implementations. VIRTUAL EVENT DATES: Financial Services - March 6, 2025 Retail & Consumer Goods - March 20, 2025 Manufacturing - March 27, 2025 Advertising, Media & Entertainment - April 3, 2025 Public Sector - April 24, 2025 Healthcare & Life Sciences - April 30, 2025 Register now at https://www.snowflake.com/Accelerate | R4: Link | AE4: 1
B6: Tues | C6: 45699 | D6: 6 a.m. | E6: Customer Testimonial- eSentire | H6: X | K6: MP4; Wrike; done | L6: 3 | M6: 14 | O6: Transforming Cybersecurity Operations | P6: eSentire Saves 50% And Builds A Data Mesh With Snowflake | Q6: Discover how eSentire transformed its cybersecurity operations with Snowflake. In this testimonial, CTO Dustin Hillard shares how the company reduced analytical costs by 50% and built a powerful data mesh using Snowflake. By leveraging hybrid tables, eSentire delivers real-time protection to its customers while the AI Data Cloud accelerates GenAI innovation—keeping security and governance at the forefront. | R6: Link | Y6: 1
